Workbook

Sheet Instrucciones
B1: 📖 INSTRUCCIONES — Cómo usar el kit
B3: Leé esto una vez antes de empezar. Te va a ahorrar tiempo.
B5: ⚙️ PASO 1 — Configuración
B6: 1. Abrí la pestaña Configuracion.
B7: 2. Escribí si tu negocio es 'Restaurante' o 'Emprendimiento'.
B8: 3. Completá nombre, moneda, margen objetivo, food cost máximo e IVA.
B9: 4. Eso es todo — el resto del kit se adapta solo.
B11: 📦 PASO 2 — Cargá tus insumos
B12: 1. Abrí la pestaña Base de Datos.
B13: 2. Completá cada insumo: nombre, categoría, proveedor, precio, unidad, consumo diario.
B14: 3. El factor de corrección es la merma AL COMPRAR (ej: ajo pierde 30% al pelar → ponés 0.30).
B15: 4. Estos datos alimentan automáticamente las recetas, sub-recetas e inventario.
... B54: Si una receta tiene más de 90 días sin revisar, aparece la alerta 🔴 en el Índice.

Sheet Configuracion
A1: ⚙️ CONFIGURACIÓN DEL KIT
A3: Completa estos datos una sola vez. Todo el kit se adapta automáticamente.
B5: TIPO DE NEGOCIO Y DATOS GENERALES
B6: Tipo de negocio: | D6: Emprendimiento | E6: Escribi "Restaurante" o "Emprendimiento"
B7: Nombre del negocio: | D7: La Repostera de Caro
B8: Moneda / símbolo: | D8: $ARS
B9: % Margen objetivo: | D9: 0.65
B10: % Food cost máximo: | D10: 0.35
B11: % IVA / impuesto: | D11: 0.21
B12: Las comisiones de delivery se configuran directamente en la hoja de Análisis de Precios.
B14: ADAPTACIÓN AUTOMÁTICA
B15: Restaurante → turnos (desayuno/almuerzo/cena), salón, barra, delivery por plataformas, múltiples proveedores.
B16: Emprendimiento → pedidos por WhatsApp, eventos, producción semanal, gastos simplificados.
B17: Inventario, recetas, sub-recetas y punto de equilibrio funcionan igual para ambos tipos.

Sheet Base de Datos
A1: 📦 BASE DE DATOS DE PRODUCTOS
A3: Registrá cada insumo una sola vez. Esta hoja alimenta el inventario, los pedidos y las recetas.
B5: Tip: Factor de corrección = merma al comprar (ej: 20% para ajo = comprás 1 kg pero usás 0.8 kg). Consumo diario en unidades de presentación.
B6: Tip: Consumo diario en unidades de presentación (ej: si usás media bolsa de harina por día → 0.5).
B8: INSUMO | C8: CATEGORÍA | D8: PROVEEDOR | E8: UNIDAD DE PRESENTACIÓN | F8: FORMATO COMPRA (cant.) | G8: UNIDAD DE USO | H8: PRECIO DE COMPRA ($) | I8: CONSUMO MÍN DIARIO | J8: CONSUMO MÁX DIARIO
B9: Harina 000 | C9: Harinas | D9: Molino Cañuelas | E9: bolsa 25 kg | F9: 25 | G9: kg | H9: 2800 | I9: 0.5 | J9: 2
B10: Azúcar | C10: Azúcares | D10: Ledesma | E10: bolsa 5 kg | F10: 5 | G10: kg | H10: 980 | I10: 0.3 | J10: 1
B11: Manteca | C11: Lácteos | D11: La Serenísima | E11: kg | F11: 1 | G11: kg | H11: 2200 | I11: 0.3 | J11: 0.8
B12: Aceite girasol | C12: Aceites | D12: Natura | E12: bidón 5 L | F12: 5 | G12: L | H12: 3800 | I12: 0.1 | J12: 0.3
B13: Huevos | C13: Lácteos | D13: Granja Bella | E13: docena | F13: 12 | G13: unidad | H13: 2400 | I13: 1 | J13: 3
B14: Leche entera | C14: Lácteos | D14: La Serenísima | E14: litro | F14: 1 | G14: L | H14: 850 | I14: 0.5 | J14: 2
B15: Crema de leche | C15: Lácteos | D15: La Serenísima | E15: litro | F15: 1 | G15: L | H15: 1600 | I15: 0.2 | J15: 0.6
B16: Queso mozzarella | C16: Lácteos | D16: Sancor | E16: kg | F16: 1 | G16: kg | H16: 4800 | I16: 0.2 | J16: 0.5
B17: Queso crema | C17: Lácteos | D17: Casancrem | E17: kg | F17: 1 | G17: kg | H17: 5200 | I17: 0.1 | J17: 0.3
B18: Ricota | C18: Lácteos | D18: La Serenísima | E18: kg | F18: 1 | G18: kg | H18: 2800 | I18: 0.1 | J18: 0.3
B19: Sal fina | C19: Condimentos | D19: Celusal | E19: kg | F19: 1 | G19: kg | H19: 420 | I19: 0.05 | J19: 0.15
B20: Polvo de hornear | C20: Harinas | D20: Belbake | E20: sobre 15 g | F20: 0.015 | G20: kg | H20: 180 | I20: 0.01 | J20: 0.03
... B38: Packaging bolsa | C38: Packaging | D38: Empaques SRL | E38: paq 100 u | F38: 100 | G38: unidad | H38: 2200 | I38: 3 | J38: 8

Sheet Inventario
A2: 📋 HOJA DE INVENTARIO
A3: =IF(Configuracion!D6="Restaurante","Imprimí esta hoja y llevala al local para el conteo físico de stock.","Usala para registrar cuánto tenés de cada insumo antes de salir a comprar.") -> Usala para registrar cuánto tenés de cada insumo antes de salir a comprar.
B5: Completá la columna 'Existencia actual' con el conteo físico. El punto de pedido y la alerta se calculan solos.
B6: Fecha del inventario: | E6: 45762 | G6: Carolina Sánchez
B7: CONTEO DE STOCK
B8: PRODUCTO | C8: CATEGORÍA | D8: UNIDAD | E8: EXISTENCIA ACTUAL | F8: UBICACIÓN / ZONA | G8: PUNTO DE PEDIDO | H8: ¿NECESITA REPOSICIÓN?
B9: ='Base de Datos'!B9 -> Harina 000 | C9: ='Base de Datos'!C9 -> Harinas | D9: ='Base de Datos'!G9 -> kg | E9: 5 | F9: Despensa | G9: =IF('Base de Datos'!J9>0,'Base de Datos'!J9*3,"") -> 6 | H9: =IF(E9="","",IF(E9<=G9,"⚠️ SÍ — REPONER","✅ OK")) -> ⚠️ SÍ — REPONER
B10: ='Base de Datos'!B10 -> Azúcar | C10: ='Base de Datos'!C10 -> Azúcares | D10: ='Base de Datos'!G10 -> kg | E10: 4 | F10: Despensa | G10: =IF('Base de Datos'!J10>0,'Base de Datos'!J10*3,"") -> 3 | H10: =IF(E10="","",IF(E10<=G10,"⚠️ SÍ — REPONER","✅ OK")) -> ✅ OK
B11: ='Base de Datos'!B11 -> Manteca | C11: ='Base de Datos'!C11 -> Lácteos | D11: ='Base de Datos'!G11 -> kg | E11: 0.2 | F11: Heladera | G11: =IF('Base de Datos'!J11>0,'Base de Datos'!J11*3,"") -> 2.4 | H11: =IF(E11="","",IF(E11<=G11,"⚠️ SÍ — REPONER","✅ OK")) -> ⚠️ SÍ — REPONER
B12: ='Base de Datos'!B12 -> Aceite girasol | C12: ='Base de Datos'!C12 -> Aceites | D12: ='Base de Datos'!G12 -> L | E12: 3.5 | F12: Despensa | G12: =IF('Base de Datos'!J12>0,'Base de Datos'!J12*3,"") -> 0.9 | H12: =IF(E12="","",IF(E12<=G12,"⚠️ SÍ — REPONER","✅ OK")) -> ✅ OK
B13: ='Base de Datos'!B13 -> Huevos | C13: ='Base de Datos'!C13 -> Lácteos | D13: ='Base de Datos'!G13 -> unidad | E13: 10 | F13: Heladera | G13: =IF('Base de Datos'!J13>0,'Base de Datos'!J13*3,"") -> 9 | H13: =IF(E13="","",IF(E13<=G13,"⚠️ SÍ — REPONER","✅ OK")) -> ✅ OK
B14: ='Base de Datos'!B14 -> Leche entera | C14: ='Base de Datos'!C14 -> Lácteos | D14: ='Base de Datos'!G14 -> L | E14: 5 | F14: Heladera | G14: =IF('Base de Datos'!J14>0,'Base de Datos'!J14*3,"") -> 6 | H14: =IF(E14="","",IF(E14<=G14,"⚠️ SÍ — REPONER","✅ OK")) -> ⚠️ SÍ — REPONER
B15: ='Base de Datos'!B15 -> Crema de leche | C15: ='Base de Datos'!C15 -> Lácteos | D15: ='Base de Datos'!G15 -> L | E15: 0.3 | F15: Heladera | G15: =IF('Base de Datos'!J15>0,'Base de Datos'!J15*3,"") -> 1.8 | H15: =IF(E15="","",IF(E15<=G15,"⚠️ SÍ — REPONER","✅ OK")) -> ⚠️ SÍ — REPONER
B16: ='Base de Datos'!B16 -> Queso mozzarella | C16: ='Base de Datos'!C16 -> Lácteos | D16: ='Base de Datos'!G16 -> kg | E16: 1.8 | F16: Heladera | G16: =IF('Base de Datos'!J16>0,'Base de Datos'!J16*3,"") -> 1.5 | H16: =IF(E16="","",IF(E16<=G16,"⚠️ SÍ — REPONER","✅ OK")) -> ✅ OK
B17: ='Base de Datos'!B17 -> Queso crema | C17: ='Base de Datos'!C17 -> Lácteos | D17: ='Base de Datos'!G17 -> kg | E17: 0.8 | F17: Heladera | G17: =IF('Base de Datos'!J17>0,'Base de Datos'!J17*3,"") -> 0.9 | H17: =IF(E17="","",IF(E17<=G17,"⚠️ SÍ — REPONER","✅ OK")) -> ⚠️ SÍ — REPONER
B18: ='Base de Datos'!B18 -> Ricota | C18: ='Base de Datos'!C18 -> Lácteos | D18: ='Base de Datos'!G18 -> kg | E18: 1.5 | F18: Heladera | G18: =IF('Base de Datos'!J18>0,'Base de Datos'!J18*3,"") -> 0.9 | H18: =IF(E18="","",IF(E18<=G18,"⚠️ SÍ — REPONER","✅ OK")) -> ✅ OK
B19: ='Base de Datos'!B19 -> Sal fina | C19: ='Base de Datos'!C19 -> Condimentos | D19: ='Base de Datos'!G19 -> kg | E19: 0.8 | F19: Despensa | G19: =IF('Base de Datos'!J19>0,'Base de Datos'!J19*3,"") -> 0.45 | H19: =IF(E19="","",IF(E19<=G19,"⚠️ SÍ — REPONER","✅ OK")) -> ✅ OK
B20: ='Base de Datos'!B20 -> Polvo de hornear | C20: ='Base de Datos'!C20 -> Harinas | D20: ='Base de Datos'!G20 -> kg | E20: 0.12 | F20: Despensa | G20: =IF('Base de Datos'!J20>0,'Base de Datos'!J20*3,"") -> 0.09 | H20: =IF(E20="","",IF(E20<=G20,"⚠️ SÍ — REPONER","✅ OK")) -> ✅ OK
... B38: ='Base de Datos'!B38 -> Packaging bolsa | C38: ='Base de Datos'!C38 -> Packaging | D38: ='Base de Datos'!G38 -> unidad | E38: 120 | F38: Depósito | G38: =IF('Base de Datos'!J38>0,'Base de Datos'!J38*3,"") -> 24 | H38: =IF(E38="","",IF(E38<=G38,"⚠️ SÍ — REPONER","✅ OK")) -> ✅ OK

Sheet Pedidos
A1: 🛒 PEDIDO SUGERIDO
A2: Generado automáticamente en base al inventario, consumo y días de reposición. Solo muestra lo que hay que pedir.
B4: Items a reponer: | E4: Valor estimado del pedido:
B5: =COUNTIF(Inventario!H9:H38,"⚠️*") -> 10 | E5: =SUMIF(B8:B53,"<>",I8:I53) -> 110995
B6: DETALLE DEL PEDIDO
B7: PRODUCTO | C7: PROVEEDOR | D7: EXISTENCIA ACTUAL | E7: PUNTO PEDIDO | F7: CANTIDAD A PEDIR (unidades presentación) | G7: UNIDAD COMPRA | H7: PRECIO UNITARIO ($) | I7: COSTO ESTIMADO ($)
B8: =IF(Inventario!E9<=Inventario!G9,'Base de Datos'!B9,"") -> Harina 000 | C8: =IF(Inventario!E9<=Inventario!G9,'Base de Datos'!D9,"") -> Molino Cañuelas | D8: =IF(Inventario!E9<=Inventario!G9,Inventario!E9,"") -> 5 | E8: =IF(Inventario!E9<=Inventario!G9,Inventario!G9,"") -> 6 | F8: =IFERROR(IF(Inventario!E9<=Inventario!G9,MAX(CEILING(('Base de Datos'!J9*3-Inventario!E9)/'Base de Datos'!F9,1),1),""),"") -> 1 | G8: =IF(Inventario!E9<=Inventario!G9,'Base de Datos'!E9,"") -> bolsa 25 kg | H8: =IF(Inventario!E9<=Inventario!G9,'Base de Datos'!H9,"") -> 2800 | I8: =IF(AND(F8<>"",H8<>""),F8*H8*'Base de Datos'!F9,"") -> 70000
B9: =IF(Inventario!E11<=Inventario!G11,'Base de Datos'!B11,"") -> Manteca | C9: =IF(Inventario!E11<=Inventario!G11,'Base de Datos'!D11,"") -> La Serenísima | D9: =IF(Inventario!E11<=Inventario!G11,Inventario!E11,"") -> 0.2 | E9: =IF(Inventario!E11<=Inventario!G11,Inventario!G11,"") -> 2.4 | F9: =IFERROR(IF(Inventario!E11<=Inventario!G11,MAX(CEILING(('Base de Datos'!J11*3-Inventario!E11)/'Base de Datos'!F11,1),1),""),"") -> 3 | G9: =IF(Inventario!E11<=Inventario!G11,'Base de Datos'!E11,"") -> kg | H9: =IF(Inventario!E11<=Inventario!G11,'Base de Datos'!H11,"") -> 2200 | I9: =IF(AND(F9<>"",H9<>""),F9*H9*'Base de Datos'!F11,"") -> 6600
B10: =IF(Inventario!E14<=Inventario!G14,'Base de Datos'!B14,"") -> Leche entera | C10: =IF(Inventario!E14<=Inventario!G14,'Base de Datos'!D14,"") -> La Serenísima | D10: =IF(Inventario!E14<=Inventario!G14,Inventario!E14,"") -> 5 | E10: =IF(Inventario!E14<=Inventario!G14,Inventario!G14,"") -> 6 | F10: =IFERROR(IF(Inventario!E14<=Inventario!G14,MAX(CEILING(('Base de Datos'!J14*3-Inventario!E14)/'Base de Datos'!F14,1),1),""),"") -> 1 | G10: =IF(Inventario!E14<=Inventario!G14,'Base de Datos'!E14,"") -> litro | H10: =IF(Inventario!E14<=Inventario!G14,'Base de Datos'!H14,"") -> 850 | I10: =IF(AND(F10<>"",H10<>""),F10*H10*'Base de Datos'!F14,"") -> 850
B11: =IF(Inventario!E15<=Inventario!G15,'Base de Datos'!B15,"") -> Crema de leche | C11: =IF(Inventario!E15<=Inventario!G15,'Base de Datos'!D15,"") -> La Serenísima | D11: =IF(Inventario!E15<=Inventario!G15,Inventario!E15,"") -> 0.3 | E11: =IF(Inventario!E15<=Inventario!G15,Inventario!G15,"") -> 1.8 | F11: =IFERROR(IF(Inventario!E15<=Inventario!G15,MAX(CEILING(('Base de Datos'!J15*3-Inventario!E15)/'Base de Datos'!F15,1),1),""),"") -> 2 | G11: =IF(Inventario!E15<=Inventario!G15,'Base de Datos'!E15,"") -> litro | H11: =IF(Inventario!E15<=Inventario!G15,'Base de Datos'!H15,"") -> 1600 | I11: =IF(AND(F11<>"",H11<>""),F11*H11*'Base de Datos'!F15,"") -> 3200
B12: =IF(Inventario!E17<=Inventario!G17,'Base de Datos'!B17,"") -> Queso crema | C12: =IF(Inventario!E17<=Inventario!G17,'Base de Datos'!D17,"") -> Casancrem | D12: =IF(Inventario!E17<=Inventario!G17,Inventario!E17,"") -> 0.8 | E12: =IF(Inventario!E17<=Inventario!G17,Inventario!G17,"") -> 0.9 | F12: =IFERROR(IF(Inventario!E17<=Inventario!G17,MAX(CEILING(('Base de Datos'!J17*3-Inventario!E17)/'Base de Datos'!F17,1),1),""),"") -> 1 | G12: =IF(Inventario!E17<=Inventario!G17,'Base de Datos'!E17,"") -> kg | H12: =IF(Inventario!E17<=Inventario!G17,'Base de Datos'!H17,"") -> 5200 | I12: =IF(AND(F12<>"",H12<>""),F12*H12*'Base de Datos'!F17,"") -> 5200
B13: =IF(Inventario!E22<=Inventario!G22,'Base de Datos'!B22,"") -> Vainilla esencia | C13: =IF(Inventario!E22<=Inventario!G22,'Base de Datos'!D22,"") -> Alicante | D13: =IF(Inventario!E22<=Inventario!G22,Inventario!E22,"") -> 0.08 | E13: =IF(Inventario!E22<=Inventario!G22,Inventario!G22,"") -> 0.09 | F13: =IFERROR(IF(Inventario!E22<=Inventario!G22,MAX(CEILING(('Base de Datos'!J22*3-Inventario!E22)/'Base de Datos'!F22,1),1),""),"") -> 1 | G13: =IF(Inventario!E22<=Inventario!G22,'Base de Datos'!E22,"") -> frasco 100ml | H13: =IF(Inventario!E22<=Inventario!G22,'Base de Datos'!H22,"") -> 650 | I13: =IF(AND(F13<>"",H13<>""),F13*H13*'Base de Datos'!F22,"") -> 65
B14: =IF(Inventario!E24<=Inventario!G24,'Base de Datos'!B24,"") -> Dulce de leche | C14: =IF(Inventario!E24<=Inventario!G24,'Base de Datos'!D24,"") -> La Salamandra | D14: =IF(Inventario!E24<=Inventario!G24,Inventario!E24,"") -> 2.8 | E14: =IF(Inventario!E24<=Inventario!G24,Inventario!G24,"") -> 3 | F14: =IFERROR(IF(Inventario!E24<=Inventario!G24,MAX(CEILING(('Base de Datos'!J24*3-Inventario!E24)/'Base de Datos'!F24,1),1),""),"") -> 1 | G14: =IF(Inventario!E24<=Inventario!G24,'Base de Datos'!E24,"") -> balde 4 kg | H14: =IF(Inventario!E24<=Inventario!G24,'Base de Datos'!H24,"") -> 3600 | I14: =IF(AND(F14<>"",H14<>""),F14*H14*'Base de Datos'!F24,"") -> 14400
B15: =IF(Inventario!E26<=Inventario!G26,'Base de Datos'!B26,"") -> Chocolate cobertura | C15: =IF(Inventario!E26<=Inventario!G26,'Base de Datos'!D26,"") -> Fenix | D15: =IF(Inventario!E26<=Inventario!G26,Inventario!E26,"") -> 0.8 | E15: =IF(Inventario!E26<=Inventario!G26,Inventario!G26,"") -> 0.9 | F15: =IFERROR(IF(Inventario!E26<=Inventario!G26,MAX(CEILING(('Base de Datos'!J26*3-Inventario!E26)/'Base de Datos'!F26,1),1),""),"") -> 1 | G15: =IF(Inventario!E26<=Inventario!G26,'Base de Datos'!E26,"") -> kg | H15: =IF(Inventario!E26<=Inventario!G26,'Base de Datos'!H26,"") -> 6800 | I15: =IF(AND(F15<>"",H15<>""),F15*H15*'Base de Datos'!F26,"") -> 6800
B16: =IF(Inventario!E29<=Inventario!G29,'Base de Datos'!B29,"") -> Carne picada | C16: =IF(Inventario!E29<=Inventario!G29,'Base de Datos'!D29,"") -> Frigorífico Amor | D16: =IF(Inventario!E29<=Inventario!G29,Inventario!E29,"") -> 1.5 | E16: =IF(Inventario!E29<=Inventario!G29,Inventario!G29,"") -> 1.5 | F16: =IFERROR(IF(Inventario!E29<=Inventario!G29,MAX(CEILING(('Base de Datos'!J29*3-Inventario!E29)/'Base de Datos'!F29,1),1),""),"") -> 1 | G16: =IF(Inventario!E29<=Inventario!G29,'Base de Datos'!E29,"") -> kg | H16: =IF(Inventario!E29<=Inventario!G29,'Base de Datos'!H29,"") -> 3200 | I16: =IF(AND(F16<>"",H16<>""),F16*H16*'Base de Datos'!F29,"") -> 3200
B17: =IF(Inventario!E33<=Inventario!G33,'Base de Datos'!B33,"") -> Limón | C17: =IF(Inventario!E33<=Inventario!G33,'Base de Datos'!D33,"") -> Verdulería Sur | D17: =IF(Inventario!E33<=Inventario!G33,Inventario!E33,"") -> 0.4 | E17: =IF(Inventario!E33<=Inventario!G33,Inventario!G33,"") -> 0.45 | F17: =IFERROR(IF(Inventario!E33<=Inventario!G33,MAX(CEILING(('Base de Datos'!J33*3-Inventario!E33)/'Base de Datos'!F33,1),1),""),"") -> 1 | G17: =IF(Inventario!E33<=Inventario!G33,'Base de Datos'!E33,"") -> kg | H17: =IF(Inventario!E33<=Inventario!G33,'Base de Datos'!H33,"") -> 680 | I17: =IF(AND(F17<>"",H17<>""),F17*H17*'Base de Datos'!F33,"") -> 680
B18: =IF(Inventario!E34<=Inventario!G34,'Base de Datos'!B34,"") | C18: =IF(Inventario!E34<=Inventario!G34,'Base de Datos'!D34,"") | D18: =IF(Inventario!E34<=Inventario!G34,Inventario!E34,"") | E18: =IF(Inventario!E34<=Inventario!G34,Inventario!G34,"") | F18: =IFERROR(IF(Inventario!E34<=Inventario!G34,MAX(CEILING(('Base de Datos'!J34*3-Inventario!E34)/'Base de Datos'!F34,1),1),""),"") | G18: =IF(Inventario!E34<=Inventario!G34,'Base de Datos'!E34,"") | H18: =IF(Inventario!E34<=Inventario!G34,'Base de Datos'!H34,"") | I18: =IF(AND(F18<>"",H18<>""),F18*H18*'Base de Datos'!F34,"")
B19: =IF(Inventario!E35<=Inventario!G35,'Base de Datos'!B35,"") | C19: =IF(Inventario!E35<=Inventario!G35,'Base de Datos'!D35,"") | D19: =IF(Inventario!E35<=Inventario!G35,Inventario!E35,"") | E19: =IF(Inventario!E35<=Inventario!G35,Inventario!G35,"") | F19: =IFERROR(IF(Inventario!E35<=Inventario!G35,MAX(CEILING(('Base de Datos'!J35*3-Inventario!E35)/'Base de Datos'!F35,1),1),""),"") | G19: =IF(Inventario!E35<=Inventario!G35,'Base de Datos'!E35,"") | H19: =IF(Inventario!E35<=Inventario!G35,'Base de Datos'!H35,"") | I19: =IF(AND(F19<>"",H19<>""),F19*H19*'Base de Datos'!F35,"")
B20: =IF(Inventario!E36<=Inventario!G36,'Base de Datos'!B36,"") | C20: =IF(Inventario!E36<=Inventario!G36,'Base de Datos'!D36,"") | D20: =IF(Inventario!E36<=Inventario!G36,Inventario!E36,"") | E20: =IF(Inventario!E36<=Inventario!G36,Inventario!G36,"") | F20: =IFERROR(IF(Inventario!E36<=Inventario!G36,MAX(CEILING(('Base de Datos'!J36*3-Inventario!E36)/'Base de Datos'!F36,1),1),""),"") | G20: =IF(Inventario!E36<=Inventario!G36,'Base de Datos'!E36,"") | H20: =IF(Inventario!E36<=Inventario!G36,'Base de Datos'!H36,"") | I20: =IF(AND(F20<>"",H20<>""),F20*H20*'Base de Datos'!F36,"")
B21: =IF(Inventario!E37<=Inventario!G37,'Base de Datos'!B37,"") | C21: =IF(Inventario!E37<=Inventario!G37,'Base de Datos'!D37,"") | D21: =IF(Inventario!E37<=Inventario!G37,Inventario!E37,"") | E21: =IF(Inventario!E37<=Inventario!G37,Inventario!G37,"") | F21: =IFERROR(IF(Inventario!E37<=Inventario!G37,MAX(CEILING(('Base de Datos'!J37*3-Inventario!E37)/'Base de Datos'!F37,1),1),""),"") | G21: =IF(Inventario!E37<=Inventario!G37,'Base de Datos'!E37,"") | H21: =IF(Inventario!E37<=Inventario!G37,'Base de Datos'!H37,"") | I21: =IF(AND(F21<>"",H21<>""),F21*H21*'Base de Datos'!F37,"")
B22: =IF(Inventario!E38<=Inventario!G38,'Base de Datos'!B38,"") | C22: =IF(Inventario!E38<=Inventario!G38,'Base de Datos'!D38,"") | D22: =IF(Inventario!E38<=Inventario!G38,Inventario!E38,"") | E22: =IF(Inventario!E38<=Inventario!G38,Inventario!G38,"") | F22: =IFERROR(IF(Inventario!E38<=Inventario!G38,MAX(CEILING(('Base de Datos'!J38*3-Inventario!E38)/'Base de Datos'!F38,1),1),""),"") | G22: =IF(Inventario!E38<=Inventario!G38,'Base de Datos'!E38,"") | H22: =IF(Inventario!E38<=Inventario!G38,'Base de Datos'!H38,"") | I22: =IF(AND(F22<>"",H22<>""),F22*H22*'Base de Datos'!F38,"")
B54: Solo aparecen los productos que necesitan reposición. Completá la columna 'Existencia actual' en la hoja Inventario para actualizar este pedido.

Sheet Ingresos y Gastos
A2: 💰 INGRESOS Y GASTOS MENSUALES
B4: Mes: | D4: Abril | E4: Año: | G4: 2025
B6: REGISTRO DEL MES
B7: TIPO | C7: CONCEPTO | D7: SEMANA 1 ($) | E7: SEMANA 2 ($) | F7: SEMANA 3 ($) | G7: SEMANA 4 ($) | H7: TOTAL MES ($)
B8: VENTAS | C8: =IF(Configuracion!D6="Restaurante","Ventas salón / mostrador","Pedidos WhatsApp / directos") -> Pedidos WhatsApp / directos | D8: 85000 | E8: 92000 | F8: 78000 | G8: 95000 | H8: =SUM(D8:G8) -> 350000
C9: =IF(Configuracion!D6="Restaurante","Delivery (plataformas)","Catering / eventos") -> Catering / eventos | D9: 45000 | E9: 0 | F9: 65000 | G9: 0 | H9: =SUM(D9:G9) -> 110000
C10: =IF(Configuracion!D6="Restaurante","Bar / bebidas","Ventas en ferias / mercados") -> Ventas en ferias / mercados | D10: 0 | E10: 15000 | F10: 0 | G10: 22000 | H10: =SUM(D10:G10) -> 37000
C11: Otros ingresos | D11: 8000 | E11: 5000 | F11: 12000 | G11: 6000 | H11: =SUM(D11:G11) -> 31000
B12: SUBTOTAL VENTAS | D12: =D8+D9+D10+D11 -> 138000 | E12: =E8+E9+E10+E11 -> 112000 | F12: =F8+F9+F10+F11 -> 155000 | G12: =G8+G9+G10+G11 -> 123000 | H12: =SUM(H8:H11) -> 528000
B14: TOTAL INGRESOS | D14: =D12 -> 138000 | E14: =E12 -> 112000 | F14: =F12 -> 155000 | G14: =G12 -> 123000 | H14: =H12 -> 528000
B16: INSUMOS Y MATERIA PRIMA | C16: =IF(Configuracion!D6="Restaurante","Proveedores comidas","Ingredientes / materia prima") -> Ingredientes / materia prima | D16: 42000 | E16: 38000 | F16: 45000 | G16: 41000 | H16: =SUM(D16:G16) -> 166000
C17: =IF(Configuracion!D6="Restaurante","Proveedores bebidas","Packaging y materiales") -> Packaging y materiales | D17: 8000 | E17: 7500 | F17: 9000 | G17: 8500 | H17: =SUM(D17:G17) -> 33000
C18: Otros insumos | D18: 3000 | E18: 2500 | F18: 3500 | G18: 2800 | H18: =SUM(D18:G18) -> 11800
B19: SUBTOTAL INSUMOS Y MATERIA PRIMA | D19: =D16+D17+D18 -> 53000 | E19: =E16+E17+E18 -> 48000 | F19: =F16+F17+F18 -> 57500 | G19: =G16+G17+G18 -> 52300 | H19: =SUM(H16:H18) -> 210800
B21: PERSONAL | C21: =IF(Configuracion!D6="Restaurante","Sueldos empleados","Colaboradores / ayuda") -> Colaboradores / ayuda | D21: 20000 | E21: 20000 | F21: 20000 | G21: 20000 | H21: =SUM(D21:G21) -> 80000
C22: Tu sueldo / retiro | D22: 20000 | E22: 20000 | F22: 20000 | G22: 20000 | H22: =SUM(D22:G22) -> 80000
C23: Cargas sociales / otros | D23: 0 | E23: 0 | F23: 0 | G23: 0 | H23: =SUM(D23:G23) -> 0
B24: SUBTOTAL PERSONAL | D24: =D21+D22+D23 -> 40000 | E24: =E21+E22+E23 -> 40000 | F24: =F21+F22+F23 -> 40000 | G24: =G21+G22+G23 -> 40000 | H24: =SUM(H21:H23) -> 160000
B26: GASTOS FIJOS | C26: Alquiler | D26: 0 | E26: 0 | F26: 0 | G26: 0 | H26: =SUM(D26:G26) -> 0
C27: Servicios (luz, gas, agua, internet) | D27: 8000 | E27: 0 | F27: 0 | G27: 0 | H27: =SUM(D27:G27) -> 8000
C28: Seguro | D28: 4000 | E28: 0 | F28: 0 | G28: 0 | H28: =SUM(D28:G28) -> 4000
C29: =IF(Configuracion!D6="Restaurante","Contador / asesoría","Plataformas / suscripciones") -> Plataformas / suscripciones | D29: 0 | E29: 0 | F29: 0 | G29: 4500 | H29: =SUM(D29:G29) -> 4500
C30: Impuestos / tasas | D30: 5000 | E30: 0 | F30: 0 | G30: 0 | H30: =SUM(D30:G30) -> 5000
C31: Otros gastos fijos | D31: 0 | E31: 0 | F31: 0 | G31: 0 | H31: =SUM(D31:G31) -> 0
B32: SUBTOTAL GASTOS FIJOS | D32: =D26+D27+D28+D29+D30+D31 -> 17000 | E32: =E26+E27+E28+E29+E30+E31 -> 0 | F32: =F26+F27+F28+F29+F30+F31 -> 0 | G32: =G26+G27+G28+G29+G30+G31 -> 4500 | H32: =SUM(H26:H31) -> 21500
B34: GASTOS VARIABLES | C34: Marketing / publicidad | D34: 8000 | E34: 6000 | F34: 9000 | G34: 7500 | H34: =SUM(D34:G34) -> 30500
C35: Mantenimiento y reparaciones | D35: 2000 | E35: 1500 | F35: 3000 | G35: 1000 | H35: =SUM(D35:G35) -> 7500
C36: Transporte / combustible | D36: 3500 | E36: 3500 | F36: 3500 | G36: 3500 | H36: =SUM(D36:G36) -> 14000
C37: Otros gastos variables | D37: 1000 | E37: 800 | F37: 1200 | G37: 900 | H37: =SUM(D37:G37) -> 3900
B38: SUBTOTAL GASTOS VARIABLES | D38: =D34+D35+D36+D37 -> 14500 | E38: =E34+E35+E36+E37 -> 11800 | F38: =F34+F35+F36+F37 -> 16700 | G38: =G34+G35+G36+G37 -> 12900 | H38: =SUM(H34:H37) -> 55900
B40: TOTAL GASTOS | D40: =D19+D24+D32+D38 -> 124500 | E40: =E19+E24+E32+E38 -> 99800 | F40: =F19+F24+F32+F38 -> 114200 | G40: =G19+G24+G32+G38 -> 109700 | H40: =H19+H24+H32+H38 -> 448200
B42: RESULTADO DEL MES | D42: =D14-D40 -> 13500 | E42: =E14-E40 -> 12200 | F42: =F14-F40 -> 40800 | G42: =G14-G40 -> 13300 | H42: =H14-H40 -> 79800
B44: =IF(H42=0,"Completa el registro para ver el resultado.",IF(H42>0,"✅ MES POSITIVO — Ganaste $"&TEXT(H42,"#,##0.00")&" este mes.","❌ MES NEGATIVO — Perdiste $"&TEXT(ABS(H42),"#,##0.00")&" — Revisá tus costos.")) -> ✅ MES POSITIVO — Ganaste $79.800,00 este mes.

Sheet Punto de Equilibrio
A1: ⚖️ PUNTO DE EQUILIBRIO
A3: =IF(Configuracion!D6="Restaurante","Adaptado para restaurante — cuánto vender por mes y por día.","Adaptado para emprendimiento — cuántos pedidos necesitas por mes.") -> Adaptado para emprendimiento — cuántos pedidos necesitas por mes.
B5: GASTOS FIJOS MENSUALES | F5: DATOS DEL NEGOCIO
B6: CONCEPTO | C6: MONTO ($) | D6: NOTAS | F6: % Costo MP — Platos: | H6: 0.35
B7: =IF(Configuracion!D6="Restaurante","Alquiler","Alquiler (si aplica)") -> Alquiler (si aplica) | C7: 0 | F7: % Costo MP — Bebidas: | H7: 0.25
B8: =IF(Configuracion!D6="Restaurante","Sueldos empleados","Tu sueldo") -> Tu sueldo | C8: 80000 | F8: % Costo MP Promedio: | H8: =IF(AND(H6>0,H7>0),(H6+H7)/2,IF(H6>0,H6,IF(H7>0,H7,""))) -> 0.3
B9: =IF(Configuracion!D6="Restaurante","Tu sueldo","Luz y gas") -> Luz y gas | C9: 8000
B10: =IF(Configuracion!D6="Restaurante","Luz","Internet") -> Internet | C10: 4500 | F10: =IF(Configuracion!D6="Restaurante","Ventas / facturación prom. mensual ($):","Facturación promedio mensual ($):") -> Facturación promedio mensual ($): | H10: 520000
B11: =IF(Configuracion!D6="Restaurante","Gas","Insumos fijos mensuales") -> Insumos fijos mensuales | C11: 15000 | F11: =IF(Configuracion!D6="Restaurante","Cantidad de comensales / ventas por mes:","Cantidad de pedidos por mes:") -> Cantidad de pedidos por mes: | H11: 85
B12: =IF(Configuracion!D6="Restaurante","Agua","Packaging fijo") -> Packaging fijo | C12: 8000 | F12: Ticket promedio (calculado): | H12: =IF(AND(H10>0,H11>0),H10/H11,"") -> 6117.6471
B13: =IF(Configuracion!D6="Restaurante","Internet / teléfono","Marketing") -> Marketing | C13: 12000 | F13: Otros costos variables por venta ($): | H13: 0
B14: =IF(Configuracion!D6="Restaurante","Seguro","Plataformas/apps") -> Plataformas/apps | C14: 0 | F14: =IF(Configuracion!D6="Restaurante","Días de apertura por mes:","Días de venta por mes:") -> Días de venta por mes: | H14: 22
B15: =IF(Configuracion!D6="Restaurante","Impuestos","Otros") -> Otros | C15: 5000
B16: =IF(Configuracion!D6="Restaurante","Delivery (abono fijo)","") | C16: 0 | F16: RESULTADOS
B17: =IF(Configuracion!D6="Restaurante","Marketing","") | C17: 0 | F17: Margen de contribución por venta ($): | H17: =IF(AND(H12>0,H8>0),H12*(1-H8)-IF(H13>0,H13,0),"") -> 4282.3529
B18: =IF(Configuracion!D6="Restaurante","Contador","") | C18: 0 | F18: Margen de contribución (%): | H18: =IF(AND(H17<>"",H12>0),H17/H12,"") -> 0.7
B19: =IF(Configuracion!D6="Restaurante","Mantenimiento","") | C19: 0 | F19: =IF(Configuracion!D6="Restaurante","Tickets mínimos / mes:","Pedidos mínimos / mes:") -> Pedidos mínimos / mes: | H19: =IF(AND(H17<>"",H17>0,C22>0),CEILING(C22/H17,1),"") -> 31
B20: =IF(Configuracion!D6="Restaurante","Préstamos","") | C20: 0 | F20: Facturación mínima mensual ($): | H20: =IF(AND(H12>0,H19<>""),H12*H19,"") -> 189647.06
B21: =IF(Configuracion!D6="Restaurante","Otros","") | C21: 0 | F21: =IF(Configuracion!D6="Restaurante","VENTAS NECESARIAS / DÍA:","PEDIDOS NECESARIOS / DÍA:") -> PEDIDOS NECESARIOS / DÍA: | H21: =IF(AND(H19<>"",H14>0),CEILING(H19/H14,1),"") -> 2
B22: TOTAL GASTOS FIJOS: | C22: =SUM(C7:C21) -> 132500 | F22: FACTURACIÓN MÍNIMA DIARIA ($): | H22: =IF(AND(H12>0,H21<>""),H12*H21,"") -> 12235.294
F23: =IF(H21="","Completá los datos para calcular el punto de equilibrio.",IF(H21>0,"✅ Calculado — necesitás "&TEXT(H21,"#,##0")&" ventas/día para cubrir tus gastos.","⚠️ Revisá los datos ingresados.")) -> ✅ Calculado — necesitás 2 ventas/día para cubrir tus gastos.

Sheet Analisis de Precios
A1: ANÁLISIS DE PRECIOS — TABLA PVP
A3: Precios, food cost, márgenes y el impacto de cada plataforma de delivery.
B6: CONFIGURACIÓN
B7: IVA / Impuesto a las ventas: | F7: =Configuracion!D11 -> 0.21
B8: % Margen objetivo (meta): | F8: =Configuracion!D9 -> 0.65
B10: TABLA DE PRECIOS
B11: RECETA | C11: COSTO UNID. ($) | D11: PRECIO SIN IVA ($) | E11: PRECIO CON IVA ($) | F11: FOOD COST % | G11: MARGEN BRUTO % | H11: MARGEN EN $ / UNIDAD | I11: SEMÁFORO
B12: ='Receta 01'!E5 -> Tacos al pastor | C12: 1750 | D12: 23140 | E12: =IF(D12>0,D12*(1+$F$7),"") -> 27999.4 | F12: =IF(AND(C12>0,D12>0),C12/D12,"") -> 0.075626621 | G12: =IF(AND(C12>0,D12>0),(D12-C12)/D12,"") -> 0.92437338 | H12: =IF(AND(C12>0,D12>0),D12-C12,"") -> 21390 | I12: =IF(G12="","—",IF(G12>=$F$8,"🟢 OK",IF(G12>=$F$8-0.1,"🟡 Ajustar","🔴 Revisar"))) -> 🟢 OK
B13: ='Receta 02'!E5 -> Alfajor de maicena | C13: 155 | D13: 1488 | E13: =IF(D13>0,D13*(1+$F$7),"") -> 1800.48 | F13: =IF(AND(C13>0,D13>0),C13/D13,"") -> 0.10416667 | G13: =IF(AND(C13>0,D13>0),(D13-C13)/D13,"") -> 0.89583333 | H13: =IF(AND(C13>0,D13>0),D13-C13,"") -> 1333 | I13: =IF(G13="","—",IF(G13>=$F$8,"🟢 OK",IF(G13>=$F$8-0.1,"🟡 Ajustar","🔴 Revisar"))) -> 🟢 OK
B14: ='Receta 03'!E5 -> Cheesecake NY | C14: 650 | D14: 6198 | E14: =IF(D14>0,D14*(1+$F$7),"") -> 7499.58 | F14: =IF(AND(C14>0,D14>0),C14/D14,"") -> 0.10487254 | G14: =IF(AND(C14>0,D14>0),(D14-C14)/D14,"") -> 0.89512746 | H14: =IF(AND(C14>0,D14>0),D14-C14,"") -> 5548 | I14: =IF(G14="","—",IF(G14>=$F$8,"🟢 OK",IF(G14>=$F$8-0.1,"🟡 Ajustar","🔴 Revisar"))) -> 🟢 OK
B15: ='Receta 04'!E5 -> Medialuna de manteca | C15: 95 | D15: 744 | E15: =IF(D15>0,D15*(1+$F$7),"") -> 900.24 | F15: =IF(AND(C15>0,D15>0),C15/D15,"") -> 0.12768817 | G15: =IF(AND(C15>0,D15>0),(D15-C15)/D15,"") -> 0.87231183 | H15: =IF(AND(C15>0,D15>0),D15-C15,"") -> 649 | I15: =IF(G15="","—",IF(G15>=$F$8,"🟢 OK",IF(G15>=$F$8-0.1,"🟡 Ajustar","🔴 Revisar"))) -> 🟢 OK
B16: ='Receta 05'!E5 -> Brownie de chocolate | C16: 110 | D16: 992 | E16: =IF(D16>0,D16*(1+$F$7),"") -> 1200.32 | F16: =IF(AND(C16>0,D16>0),C16/D16,"") -> 0.1108871 | G16: =IF(AND(C16>0,D16>0),(D16-C16)/D16,"") -> 0.8891129 | H16: =IF(AND(C16>0,D16>0),D16-C16,"") -> 882 | I16: =IF(G16="","—",IF(G16>=$F$8,"🟢 OK",IF(G16>=$F$8-0.1,"🟡 Ajustar","🔴 Revisar"))) -> 🟢 OK
B17: ='Receta 06'!E5 -> Muffin de vainilla con limón | C17: 85 | D17: 785 | E17: =IF(D17>0,D17*(1+$F$7),"") -> 949.85 | F17: =IF(AND(C17>0,D17>0),C17/D17,"") -> 0.10828025 | G17: =IF(AND(C17>0,D17>0),(D17-C17)/D17,"") -> 0.89171975 | H17: =IF(AND(C17>0,D17>0),D17-C17,"") -> 700 | I17: =IF(G17="","—",IF(G17>=$F$8,"🟢 OK",IF(G17>=$F$8-0.1,"🟡 Ajustar","🔴 Revisar"))) -> 🟢 OK
B18: ='Receta 07'!E5 -> Porción de tarta de ricota | C18: 320 | D18: 2893 | E18: =IF(D18>0,D18*(1+$F$7),"") -> 3500.53 | F18: =IF(AND(C18>0,D18>0),C18/D18,"") -> 0.11061182 | G18: =IF(AND(C18>0,D18>0),(D18-C18)/D18,"") -> 0.88938818 | H18: =IF(AND(C18>0,D18>0),D18-C18,"") -> 2573 | I18: =IF(G18="","—",IF(G18>=$F$8,"🟢 OK",IF(G18>=$F$8-0.1,"🟡 Ajustar","🔴 Revisar"))) -> 🟢 OK
B19: ='Receta 08'!E5 -> Cookie de chocolate y nueces | C19: 65 | D19: 579 | E19: =IF(D19>0,D19*(1+$F$7),"") -> 700.59 | F19: =IF(AND(C19>0,D19>0),C19/D19,"") -> 0.11226252 | G19: =IF(AND(C19>0,D19>0),(D19-C19)/D19,"") -> 0.88773748 | H19: =IF(AND(C19>0,D19>0),D19-C19,"") -> 514 | I19: =IF(G19="","—",IF(G19>=$F$8,"🟢 OK",IF(G19>=$F$8-0.1,"🟡 Ajustar","🔴 Revisar"))) -> 🟢 OK
B20: ='Receta 09'!E5 -> Pionono relleno de dulce de leche | C20: 1850 | D20: 18182 | E20: =IF(D20>0,D20*(1+$F$7),"") -> 22000.22 | F20: =IF(AND(C20>0,D20>0),C20/D20,"") -> 0.10174898 | G20: =IF(AND(C20>0,D20>0),(D20-C20)/D20,"") -> 0.89825102 | H20: =IF(AND(C20>0,D20>0),D20-C20,"") -> 16332 | I20: =IF(G20="","—",IF(G20>=$F$8,"🟢 OK",IF(G20>=$F$8-0.1,"🟡 Ajustar","🔴 Revisar"))) -> 🟢 OK
B21: ='Receta 10'!E5 -> Budín de naranja (por porción) | C21: 145 | D21: 1322 | E21: =IF(D21>0,D21*(1+$F$7),"") -> 1599.62 | F21: =IF(AND(C21>0,D21>0),C21/D21,"") -> 0.1096823 | G21: =IF(AND(C21>0,D21>0),(D21-C21)/D21,"") -> 0.8903177 | H21: =IF(AND(C21>0,D21>0),D21-C21,"") -> 1177 | I21: =IF(G21="","—",IF(G21>=$F$8,"🟢 OK",IF(G21>=$F$8-0.1,"🟡 Ajustar","🔴 Revisar"))) -> 🟢 OK
B22: ='Receta 11'!E5 -> Torta helada de dulce de leche (por porción) | C22: 520 | D22: 5372 | E22: =IF(D22>0,D22*(1+$F$7),"") -> 6500.12 | F22: =IF(AND(C22>0,D22>0),C22/D22,"") -> 0.096798213 | G22: =IF(AND(C22>0,D22>0),(D22-C22)/D22,"") -> 0.90320179 | H22: =IF(AND(C22>0,D22>0),D22-C22,"") -> 4852 | I22: =IF(G22="","—",IF(G22>=$F$8,"🟢 OK",IF(G22>=$F$8-0.1,"🟡 Ajustar","🔴 Revisar"))) -> 🟢 OK
B23: ='Receta 12'!E5 -> Factura de dulce de leche | C23: 130 | D23: 1157 | E23: =IF(D23>0,D23*(1+$F$7),"") -> 1399.97 | F23: =IF(AND(C23>0,D23>0),C23/D23,"") -> 0.11235955 | G23: =IF(AND(C23>0,D23>0),(D23-C23)/D23,"") -> 0.88764045 | H23: =IF(AND(C23>0,D23>0),D23-C23,"") -> 1027 | I23: =IF(G23="","—",IF(G23>=$F$8,"🟢 OK",IF(G23>=$F$8-0.1,"🟡 Ajustar","🔴 Revisar"))) -> 🟢 OK
B24: ='Receta 13'!E5 -> Tostada francesa con canela | C24: 185 | D24: 1653 | E24: =IF(D24>0,D24*(1+$F$7),"") -> 2000.13 | F24: =IF(AND(C24>0,D24>0),C24/D24,"") -> 0.11191773 | G24: =IF(AND(C24>0,D24>0),(D24-C24)/D24,"") -> 0.88808227 | H24: =IF(AND(C24>0,D24>0),D24-C24,"") -> 1468 | I24: =IF(G24="","—",IF(G24>=$F$8,"🟢 OK",IF(G24>=$F$8-0.1,"🟡 Ajustar","🔴 Revisar"))) -> 🟢 OK
B25: ='Receta 14'!E5 -> Porción de bizcochuelo vainilla | C25: 380 | D25: 3471 | E25: =IF(D25>0,D25*(1+$F$7),"") -> 4199.91 | F25: =IF(AND(C25>0,D25>0),C25/D25,"") -> 0.10947854 | G25: =IF(AND(C25>0,D25>0),(D25-C25)/D25,"") -> 0.89052146 | H25: =IF(AND(C25>0,D25>0),D25-C25,"") -> 3091 | I25: =IF(G25="","—",IF(G25>=$F$8,"🟢 OK",IF(G25>=$F$8-0.1,"🟡 Ajustar","🔴 Revisar"))) -> 🟢 OK
B26: ='Receta 15'!E5 -> Merengue individual | C26: 35 | D26: 331 | E26: =IF(D26>0,D26*(1+$F$7),"") -> 400.51 | F26: =IF(AND(C26>0,D26>0),C26/D26,"") -> 0.10574018 | G26: =IF(AND(C26>0,D26>0),(D26-C26)/D26,"") -> 0.89425982 | H26: =IF(AND(C26>0,D26>0),D26-C26,"") -> 296 | I26: =IF(G26="","—",IF(G26>=$F$8,"🟢 OK",IF(G26>=$F$8-0.1,"🟡 Ajustar","🔴 Revisar"))) -> 🟢 OK
B27: ='Receta 16'!E5 -> Palmerita de canela | C27: 38 | D27: 372 | E27: =IF(D27>0,D27*(1+$F$7),"") -> 450.12 | F27: =IF(AND(C27>0,D27>0),C27/D27,"") -> 0.10215054 | G27: =IF(AND(C27>0,D27>0),(D27-C27)/D27,"") -> 0.89784946 | H27: =IF(AND(C27>0,D27>0),D27-C27,"") -> 334 | I27: =IF(G27="","—",IF(G27>=$F$8,"🟢 OK",IF(G27>=$F$8-0.1,"🟡 Ajustar","🔴 Revisar"))) -> 🟢 OK
B28: ='Receta 17'!E5 -> Prepizza individual | C28: 980 | D28: 7851 | E28: =IF(D28>0,D28*(1+$F$7),"") -> 9499.71 | F28: =IF(AND(C28>0,D28>0),C28/D28,"") -> 0.12482486 | G28: =IF(AND(C28>0,D28>0),(D28-C28)/D28,"") -> 0.87517514 | H28: =IF(AND(C28>0,D28>0),D28-C28,"") -> 6871 | I28: =IF(G28="","—",IF(G28>=$F$8,"🟢 OK",IF(G28>=$F$8-0.1,"🟡 Ajustar","🔴 Revisar"))) -> 🟢 OK
B29: ='Receta 18'!E5 -> Empanada frita de carne | C29: 120 | D29: 1074 | E29: =IF(D29>0,D29*(1+$F$7),"") -> 1299.54 | F29: =IF(AND(C29>0,D29>0),C29/D29,"") -> 0.11173184 | G29: =IF(AND(C29>0,D29>0),(D29-C29)/D29,"") -> 0.88826816 | H29: =IF(AND(C29>0,D29>0),D29-C29,"") -> 954 | I29: =IF(G29="","—",IF(G29>=$F$8,"🟢 OK",IF(G29>=$F$8-0.1,"🟡 Ajustar","🔴 Revisar"))) -> 🟢 OK
B30: ='Receta 19'!E5 -> Porción de banana bread con nueces | C30: 175 | D30: 1570 | E30: =IF(D30>0,D30*(1+$F$7),"") -> 1899.7 | F30: =IF(AND(C30>0,D30>0),C30/D30,"") -> 0.11146497 | G30: =IF(AND(C30>0,D30>0),(D30-C30)/D30,"") -> 0.88853503 | H30: =IF(AND(C30>0,D30>0),D30-C30,"") -> 1395 | I30: =IF(G30="","—",IF(G30>=$F$8,"🟢 OK",IF(G30>=$F$8-0.1,"🟡 Ajustar","🔴 Revisar"))) -> 🟢 OK
B31: ='Receta 20'!E5 -> Flan casero con dulce de leche | C31: 195 | D31: 1736 | E31: =IF(D31>0,D31*(1+$F$7),"") -> 2100.56 | F31: =IF(AND(C31>0,D31>0),C31/D31,"") -> 0.11232719 | G31: =IF(AND(C31>0,D31>0),(D31-C31)/D31,"") -> 0.88767281 | H31: =IF(AND(C31>0,D31>0),D31-C31,"") -> 1541 | I31: =IF(G31="","—",IF(G31>=$F$8,"🟢 OK",IF(G31>=$F$8-0.1,"🟡 Ajustar","🔴 Revisar"))) -> 🟢 OK

Sheet Indice de Recetas
B1: 📋 ÍNDICE DE RECETAS
B2: Resumen de todas tus recetas. Clic en el nombre para ir directo a la receta.
B3: Recetas costeadas: | D3: Food cost promedio: | G3: A revisar (>90 días):
B4: =COUNTA(C7:C26) -> 20 | D4: =IFERROR(AVERAGEIF(F7:F26,">"&0),"—") -> 0.089426887 | G4: =COUNTIF(I7:I26,"*Revisar*") -> 1
B6: LISTA DE RECETAS — Hace clic en el nombre para ir a la receta
B7: NOMBRE | C7: CATEGORÍA | D7: COSTO/UNIDAD ($) | E7: PRECIO ($) | F7: FOOD COST % | G7: MARGEN % | H7: ÚLTIMA REVISIÓN | I7: ESTADO
B8: ='Receta 01'!E5 -> Tacos al pastor | C8: Tortas | D8: 1750 | E8: 28000 | F8: =IF(AND(D8>0,E8>0),D8/E8,"") -> 0.0625 | G8: =IF(AND(D8>0,E8>0),(E8-D8)/E8,"") -> 0.9375 | H8: ='Receta 01'!E10 -> 46113 | I8: =IF(D8=0,"⚪ Sin costear",IF(H8="","⚪ Sin fecha",IF((TODAY()-H8)>90,"🔴 Revisar","🟢 Al día"))) -> 🟢 Al día
B9: ='Receta 02'!E5 -> Alfajor de maicena | C9: Alfajores | D9: 155 | E9: 1800 | F9: =IF(AND(D9>0,E9>0),D9/E9,"") -> 0.086111111 | G9: =IF(AND(D9>0,E9>0),(E9-D9)/E9,"") -> 0.91388889 | H9: ='Receta 02'!E10 -> 46109 | I9: =IF(D9=0,"⚪ Sin costear",IF(H9="","⚪ Sin fecha",IF((TODAY()-H9)>90,"🔴 Revisar","🟢 Al día"))) -> 🟢 Al día
B10: ='Receta 03'!E5 -> Cheesecake NY | C10: Tartas frías | D10: 650 | E10: 7500 | F10: =IF(AND(D10>0,E10>0),D10/E10,"") -> 0.086666667 | G10: =IF(AND(D10>0,E10>0),(E10-D10)/E10,"") -> 0.91333333 | H10: ='Receta 03'!E10 -> 46117 | I10: =IF(D10=0,"⚪ Sin costear",IF(H10="","⚪ Sin fecha",IF((TODAY()-H10)>90,"🔴 Revisar","🟢 Al día"))) -> 🟢 Al día
B11: ='Receta 04'!E5 -> Medialuna de manteca | C11: Facturas | D11: 95 | E11: 900 | F11: =IF(AND(D11>0,E11>0),D11/E11,"") -> 0.10555556 | G11: =IF(AND(D11>0,E11>0),(E11-D11)/E11,"") -> 0.89444444 | H11: ='Receta 04'!E10 -> 46101 | I11: =IF(D11=0,"⚪ Sin costear",IF(H11="","⚪ Sin fecha",IF((TODAY()-H11)>90,"🔴 Revisar","🟢 Al día"))) -> 🟢 Al día
B12: ='Receta 05'!E5 -> Brownie de chocolate | C12: Chocolates | D12: 110 | E12: 1200 | F12: =IF(AND(D12>0,E12>0),D12/E12,"") -> 0.091666667 | G12: =IF(AND(D12>0,E12>0),(E12-D12)/E12,"") -> 0.90833333 | H12: ='Receta 05'!E10 -> 46122 | I12: =IF(D12=0,"⚪ Sin costear",IF(H12="","⚪ Sin fecha",IF((TODAY()-H12)>90,"🔴 Revisar","🟢 Al día"))) -> 🟢 Al día
B13: ='Receta 06'!E5 -> Muffin de vainilla con limón | C13: Muffins | D13: 85 | E13: 950 | F13: =IF(AND(D13>0,E13>0),D13/E13,"") -> 0.089473684 | G13: =IF(AND(D13>0,E13>0),(E13-D13)/E13,"") -> 0.91052632 | H13: ='Receta 06'!E10 -> 46096 | I13: =IF(D13=0,"⚪ Sin costear",IF(H13="","⚪ Sin fecha",IF((TODAY()-H13)>90,"🔴 Revisar","🟢 Al día"))) -> 🟢 Al día
B14: ='Receta 07'!E5 -> Porción de tarta de ricota | C14: Tartas | D14: 320 | E14: 3500 | F14: =IF(AND(D14>0,E14>0),D14/E14,"") -> 0.091428571 | G14: =IF(AND(D14>0,E14>0),(E14-D14)/E14,"") -> 0.90857143 | H14: ='Receta 07'!E10 -> 46114 | I14: =IF(D14=0,"⚪ Sin costear",IF(H14="","⚪ Sin fecha",IF((TODAY()-H14)>90,"🔴 Revisar","🟢 Al día"))) -> 🟢 Al día
B15: ='Receta 08'!E5 -> Cookie de chocolate y nueces | C15: Galletas | D15: 65 | E15: 700 | F15: =IF(AND(D15>0,E15>0),D15/E15,"") -> 0.092857143 | G15: =IF(AND(D15>0,E15>0),(E15-D15)/E15,"") -> 0.90714286 | H15: ='Receta 08'!E10 -> 46120 | I15: =IF(D15=0,"⚪ Sin costear",IF(H15="","⚪ Sin fecha",IF((TODAY()-H15)>90,"🔴 Revisar","🟢 Al día"))) -> 🟢 Al día
B16: ='Receta 09'!E5 -> Pionono relleno de dulce de leche | C16: Rellenos | D16: 1850 | E16: 22000 | F16: =IF(AND(D16>0,E16>0),D16/E16,"") -> 0.084090909 | G16: =IF(AND(D16>0,E16>0),(E16-D16)/E16,"") -> 0.91590909 | H16: ='Receta 09'!E10 -> 46078 | I16: =IF(D16=0,"⚪ Sin costear",IF(H16="","⚪ Sin fecha",IF((TODAY()-H16)>90,"🔴 Revisar","🟢 Al día"))) -> 🟢 Al día
B17: ='Receta 10'!E5 -> Budín de naranja (por porción) | C17: Budines | D17: 145 | E17: 1600 | F17: =IF(AND(D17>0,E17>0),D17/E17,"") -> 0.090625 | G17: =IF(AND(D17>0,E17>0),(E17-D17)/E17,"") -> 0.909375 | H17: ='Receta 10'!E10 -> 46111 | I17: =IF(D17=0,"⚪ Sin costear",IF(H17="","⚪ Sin fecha",IF((TODAY()-H17)>90,"🔴 Revisar","🟢 Al día"))) -> 🟢 Al día
B18: ='Receta 11'!E5 -> Torta helada de dulce de leche (por porción) | C18: Helados | D18: 520 | E18: 6500 | F18: =IF(AND(D18>0,E18>0),D18/E18,"") -> 0.08 | G18: =IF(AND(D18>0,E18>0),(E18-D18)/E18,"") -> 0.92 | H18: ='Receta 11'!E10 -> 46124 | I18: =IF(D18=0,"⚪ Sin costear",IF(H18="","⚪ Sin fecha",IF((TODAY()-H18)>90,"🔴 Revisar","🟢 Al día"))) -> 🟢 Al día
B19: ='Receta 12'!E5 -> Factura de dulce de leche | C19: Facturas | D19: 130 | E19: 1400 | F19: =IF(AND(D19>0,E19>0),D19/E19,"") -> 0.092857143 | G19: =IF(AND(D19>0,E19>0),(E19-D19)/E19,"") -> 0.90714286 | H19: ='Receta 12'!E10 -> 46103 | I19: =IF(D19=0,"⚪ Sin costear",IF(H19="","⚪ Sin fecha",IF((TODAY()-H19)>90,"🔴 Revisar","🟢 Al día"))) -> 🟢 Al día
B20: ='Receta 13'!E5 -> Tostada francesa con canela | C20: Desayuno | D20: 0 | E20: 0 | F20: =IF(AND(D20>0,E20>0),D20/E20,"") | G20: =IF(AND(D20>0,E20>0),(E20-D20)/E20,"") | H20: ='Receta 13'!E10 -> 45731 | I20: =IF(D20=0,"⚪ Sin costear",IF(H20="","⚪ Sin fecha",IF((TODAY()-H20)>90,"🔴 Revisar","🟢 Al día"))) -> ⚪ Sin costear
B21: ='Receta 14'!E5 -> Porción de bizcochuelo vainilla | C21: Bizcochuelos | D21: 0 | E21: 0 | F21: =IF(AND(D21>0,E21>0),D21/E21,"") | G21: =IF(AND(D21>0,E21>0),(E21-D21)/E21,"") | H21: ='Receta 14'!E10 -> 45736 | I21: =IF(D21=0,"⚪ Sin costear",IF(H21="","⚪ Sin fecha",IF((TODAY()-H21)>90,"🔴 Revisar","🟢 Al día"))) -> ⚪ Sin costear
B22: ='Receta 15'!E5 -> Merengue individual | C22: Merengues | D22: 0 | E22: 0 | F22: =IF(AND(D22>0,E22>0),D22/E22,"") | G22: =IF(AND(D22>0,E22>0),(E22-D22)/E22,"") | H22: ='Receta 15'!E10 -> 45716 | I22: =IF(D22=0,"⚪ Sin costear",IF(H22="","⚪ Sin fecha",IF((TODAY()-H22)>90,"🔴 Revisar","🟢 Al día"))) -> ⚪ Sin costear
B23: ='Receta 16'!E5 -> Palmerita de canela | C23: Galletas | D23: 0 | E23: 0 | F23: =IF(AND(D23>0,E23>0),D23/E23,"") | G23: =IF(AND(D23>0,E23>0),(E23-D23)/E23,"") | H23: ='Receta 16'!E10 -> 45726 | I23: =IF(D23=0,"⚪ Sin costear",IF(H23="","⚪ Sin fecha",IF((TODAY()-H23)>90,"🔴 Revisar","🟢 Al día"))) -> ⚪ Sin costear
B24: ='Receta 17'!E5 -> Prepizza individual | C24: Saladas | D24: 980 | E24: 9500 | F24: =IF(AND(D24>0,E24>0),D24/E24,"") -> 0.10315789 | G24: =IF(AND(D24>0,E24>0),(E24-D24)/E24,"") -> 0.89684211 | H24: ='Receta 17'!E10 -> 46117 | I24: =IF(D24=0,"⚪ Sin costear",IF(H24="","⚪ Sin fecha",IF((TODAY()-H24)>90,"🔴 Revisar","🟢 Al día"))) -> 🟢 Al día
B25: ='Receta 18'!E5 -> Empanada frita de carne | C25: Empanadas | D25: 120 | E25: 1300 | F25: =IF(AND(D25>0,E25>0),D25/E25,"") -> 0.092307692 | G25: =IF(AND(D25>0,E25>0),(E25-D25)/E25,"") -> 0.90769231 | H25: ='Receta 18'!E10 -> 46120 | I25: =IF(D25=0,"⚪ Sin costear",IF(H25="","⚪ Sin fecha",IF((TODAY()-H25)>90,"🔴 Revisar","🟢 Al día"))) -> 🟢 Al día
B26: ='Receta 19'!E5 -> Porción de banana bread con nueces | C26: Budines | D26: 175 | E26: 1900 | F26: =IF(AND(D26>0,E26>0),D26/E26,"") -> 0.092105263 | G26: =IF(AND(D26>0,E26>0),(E26-D26)/E26,"") -> 0.90789474 | H26: ='Receta 19'!E10 -> 45744 | I26: =IF(D26=0,"⚪ Sin costear",IF(H26="","⚪ Sin fecha",IF((TODAY()-H26)>90,"🔴 Revisar","🟢 Al día"))) -> 🔴 Revisar
B27: ='Receta 20'!E5 -> Flan casero con dulce de leche | C27: Flanes | D27: 195 | E27: 2100 | F27: =IF(AND(D27>0,E27>0),D27/E27,"") -> 0.092857143 | G27: =IF(AND(D27>0,E27>0),(E27-D27)/E27,"") -> 0.90714286 | H27: ='Receta 20'!E10 -> 45750 | I27: =IF(D27=0,"⚪ Sin costear",IF(H27="","⚪ Sin fecha",IF((TODAY()-H27)>90,"🔴 Revisar","🟢 Al día"))) -> 🔴 Revisar

Sheet Sub-recetas
C1: SUB-RECETAS
A5: ÍNDICE | C5: ▶ SUB-RECETA 01
A6: → 01 | C6: Nombre: | D6: Dulce de leche casero
A7: → 02 | C7: Peso crudo total (g/ml): | D7: 1000 | E7: Peso final utilizable (g/ml): | F7: 820
A8: → 03 | C8: % Margen de error: | D8: 0.05
A9: → 04
A10: → 05 | C10: INGREDIENTE | D10: CANTIDAD | E10: UNIDAD | F10: COSTO DE PRODUCCIÓN ($)
A11: → 06 | C11: Leche entera | D11: 800 | E11: ml | F11: {=IF(OR(C11="",D11=""),"",D11*IFERROR(INDEX('Base de Datos'!$H$9:$H$68/'Base de Datos'!$F$9:$F$68*(1+IF('Base de Datos'!$I$9:$I$68="",0,'Base de Datos'!$I$9:$I$68)),MATCH(C11,'Base de Datos'!$B$9:$B$68,0)),0))} -> 1020000
A12: → 07 | C12: Azúcar | D12: 250 | E12: gramo | F12: {=IF(OR(C12="",D12=""),"",D12*IFERROR(INDEX('Base de Datos'!$H$9:$H$68/'Base de Datos'!$F$9:$F$68*(1+IF('Base de Datos'!$I$9:$I$68="",0,'Base de Datos'!$I$9:$I$68)),MATCH(C12,'Base de Datos'!$B$9:$B$68,0)),0))} -> 63700
A13: → 08 | C13: Manteca | D13: 20 | E13: gramo | F13: {=IF(OR(C13="",D13=""),"",D13*IFERROR(INDEX('Base de Datos'!$H$9:$H$68/'Base de Datos'!$F$9:$F$68*(1+IF('Base de Datos'!$I$9:$I$68="",0,'Base de Datos'!$I$9:$I$68)),MATCH(C13,'Base de Datos'!$B$9:$B$68,0)),0))} -> 57200
A14: → 09 | F14: {=IF(OR(C14="",D14=""),"",D14*IFERROR(INDEX('Base de Datos'!$H$9:$H$68/'Base de Datos'!$F$9:$F$68*(1+IF('Base de Datos'!$I$9:$I$68="",0,'Base de Datos'!$I$9:$I$68)),MATCH(C14,'Base de Datos'!$B$9:$B$68,0)),0))}
A15: → 10 | F15: {=IF(OR(C15="",D15=""),"",D15*IFERROR(INDEX('Base de Datos'!$H$9:$H$68/'Base de Datos'!$F$9:$F$68*(1+IF('Base de Datos'!$I$9:$I$68="",0,'Base de Datos'!$I$9:$I$68)),MATCH(C15,'Base de Datos'!$B$9:$B$68,0)),0))}
A16: → 11 | F16: {=IF(OR(C16="",D16=""),"",D16*IFERROR(INDEX('Base de Datos'!$H$9:$H$68/'Base de Datos'!$F$9:$F$68*(1+IF('Base de Datos'!$I$9:$I$68="",0,'Base de Datos'!$I$9:$I$68)),MATCH(C16,'Base de Datos'!$B$9:$B$68,0)),0))}
A17: → 12 | F17: {=IF(OR(C17="",D17=""),"",D17*IFERROR(INDEX('Base de Datos'!$H$9:$H$68/'Base de Datos'!$F$9:$F$68*(1+IF('Base de Datos'!$I$9:$I$68="",0,'Base de Datos'!$I$9:$I$68)),MATCH(C17,'Base de Datos'!$B$9:$B$68,0)),0))}
A18: → 13 | F18: {=IF(OR(C18="",D18=""),"",D18*IFERROR(INDEX('Base de Datos'!$H$9:$H$68/'Base de Datos'!$F$9:$F$68*(1+IF('Base de Datos'!$I$9:$I$68="",0,'Base de Datos'!$I$9:$I$68)),MATCH(C18,'Base de Datos'!$B$9:$B$68,0)),0))}
A19: → 14 | F19: {=IF(OR(C19="",D19=""),"",D19*IFERROR(INDEX('Base de Datos'!$H$9:$H$68/'Base de Datos'!$F$9:$F$68*(1+IF('Base de Datos'!$I$9:$I$68="",0,'Base de Datos'!$I$9:$I$68)),MATCH(C19,'Base de Datos'!$B$9:$B$68,0)),0))}
A20: → 15 | F20: {=IF(OR(C20="",D20=""),"",D20*IFERROR(INDEX('Base de Datos'!$H$9:$H$68/'Base de Datos'!$F$9:$F$68*(1+IF('Base de Datos'!$I$9:$I$68="",0,'Base de Datos'!$I$9:$I$68)),MATCH(C20,'Base de Datos'!$B$9:$B$68,0)),0))}
F21: {=IF(OR(C21="",D21=""),"",D21*IFERROR(INDEX('Base de Datos'!$H$9:$H$68/'Base de Datos'!$F$9:$F$68*(1+IF('Base de Datos'!$I$9:$I$68="",0,'Base de Datos'!$I$9:$I$68)),MATCH(C21,'Base de Datos'!$B$9:$B$68,0)),0))}
F22: {=IF(OR(C22="",D22=""),"",D22*IFERROR(INDEX('Base de Datos'!$H$9:$H$68/'Base de Datos'!$F$9:$F$68*(1+IF('Base de Datos'!$I$9:$I$68="",0,'Base de Datos'!$I$9:$I$68)),MATCH(C22,'Base de Datos'!$B$9:$B$68,0)),0))}
C24: RESULTADOS
C25: Costo total ingredientes | D25: =SUM(F11:F22) -> 1140900
C26: Margen de error aplicado | D26: =D25*D8 -> 57045
C27: Costo total de producción | D27: =D25+D26 -> 1197945
C28: % Merma total | D28: =D8 -> 0.05
C29: Peso final utilizable (g/ml) | D29: =F7 -> 820
C30: COSTO POR UNIDAD | F30: =IF(AND(D27>0,F7>0),D27/F7,"") -> 1460.9085
C31: Para usar en una receta: escribí exactamente el mismo nombre que pusiste en "Nombre" arriba.
A33: SR02 | C33: ▶ SUB-RECETA 02
C34: Nombre: | D34: Crema pastelera
C35: Peso crudo total (g/ml): | D35: 600 | E35: Peso final utilizable (g/ml): | F35: 550
C36: % Margen de error: | D36: 0.04
C38: INGREDIENTE | D38: CANTIDAD | E38: UNIDAD | F38: COSTO DE PRODUCCIÓN ($)
C39: Leche entera | D39: 500 | E39: ml | F39: {=IF(OR(C39="",D39=""),"",D39*IFERROR(INDEX('Base de Datos'!$H$9:$H$68/'Base de Datos'!$F$9:$F$68*(1+IF('Base de Datos'!$I$9:$I$68="",0,'Base de Datos'!$I$9:$I$68)),MATCH(C39,'Base de Datos'!$B$9:$B$68,0)),0))} -> 637500
C40: Azúcar | D40: 120 | E40: gramo | F40: {=IF(OR(C40="",D40=""),"",D40*IFERROR(INDEX('Base de Datos'!$H$9:$H$68/'Base de Datos'!$F$9:$F$68*(1+IF('Base de Datos'!$I$9:$I$68="",0,'Base de Datos'!$I$9:$I$68)),MATCH(C40,'Base de Datos'!$B$9:$B$68,0)),0))} -> 30576
C41: Huevos | D41: 3 | E41: unidad | F41: {=IF(OR(C41="",D41=""),"",D41*IFERROR(INDEX('Base de Datos'!$H$9:$H$68/'Base de Datos'!$F$9:$F$68*(1+IF('Base de Datos'!$I$9:$I$68="",0,'Base de Datos'!$I$9:$I$68)),MATCH(C41,'Base de Datos'!$B$9:$B$68,0)),0))} -> 1200
C42: Manteca | D42: 30 | E42: gramo | F42: {=IF(OR(C42="",D42=""),"",D42*IFERROR(INDEX('Base de Datos'!$H$9:$H$68/'Base de Datos'!$F$9:$F$68*(1+IF('Base de Datos'!$I$9:$I$68="",0,'Base de Datos'!$I$9:$I$68)),MATCH(C42,'Base de Datos'!$B$9:$B$68,0)),0))} -> 85800
C43: Harina 000 | D43: 40 | E43: gramo | F43: {=IF(OR(C43="",D43=""),"",D43*IFERROR(INDEX('Base de Datos'!$H$9:$H$68/'Base de Datos'!$F$9:$F$68*(1+IF('Base de Datos'!$I$9:$I$68="",0,'Base de Datos'!$I$9:$I$68)),MATCH(C43,'Base de Datos'!$B$9:$B$68,0)),0))} -> 6720
F44: {=IF(OR(C44="",D44=""),"",D44*IFERROR(INDEX('Base de Datos'!$H$9:$H$68/'Base de Datos'!$F$9:$F$68*(1+IF('Base de Datos'!$I$9:$I$68="",0,'Base de Datos'!$I$9:$I$68)),MATCH(C44,'Base de Datos'!$B$9:$B$68,0)),0))}
F45: {=IF(OR(C45="",D45=""),"",D45*IFERROR(INDEX('Base de Datos'!$H$9:$H$68/'Base de Datos'!$F$9:$F$68*(1+IF('Base de Datos'!$I$9:$I$68="",0,'Base de Datos'!$I$9:$I$68)),MATCH(C45,'Base de Datos'!$B$9:$B$68,0)),0))}
F46: {=IF(OR(C46="",D46=""),"",D46*IFERROR(INDEX('Base de Datos'!$H$9:$H$68/'Base de Datos'!$F$9:$F$68*(1+IF('Base de Datos'!$I$9:$I$68="",0,'Base de Datos'!$I$9:$I$68)),MATCH(C46,'Base de Datos'!$B$9:$B$68,0)),0))}
...

Sheet Receta 01
A1: 🍳 RECETA 01
B4: DATOS DE LA RECETA
B5: Nombre: | E5: Tacos al pastor
B6: Porciones / unidades: | E6: 1
B7: % Merma de producción: | E7: 0.05
B8: % Margen de ganancia: | E8: =Configuracion!D9 -> 0.65
B9: Precio de venta actual ($): | E9: 28000
B10: Fecha último costeo: | E10: 46113
B11: =IF(E10="","⚪ Ingresá la fecha de costeo.",IF((TODAY()-E10)>90,"🔴 Hace más de 90 días sin revisar — actualizá los costos","🟢 Al día — revisada hace "&(TODAY()-E10)&" días")) -> 🟢 Al día — revisada hace 24 días
B13: INGREDIENTE / SUB-RECETA | C13: CANTIDAD POR PORCIÓN | D13: UNIDAD DE MEDIDA | E13: COSTO DE PRODUCCIÓN ($)
B14: Harina 000 | C14: 250 | D14: gramo | E14: {=IF(OR(B14="",C14=""),"",C14*IFERROR(INDEX('Base de Datos'!$H$9:$H$68/'Base de Datos'!$F$9:$F$68*(1+IF('Base de Datos'!$I$9:$I$68="",0,'Base de Datos'!$I$9:$I$68)),MATCH(B14,'Base de Datos'!$B$9:$B$68,0)),IFERROR(INDEX('Sub-recetas'!$D$428:$D$442,MATCH(B14,'Sub-recetas'!$C$428:$C$442,0)),0)))} -> 42000
B15: Azúcar | C15: 200 | D15: gramo | E15: {=IF(OR(B15="",C15=""),"",C15*IFERROR(INDEX('Base de Datos'!$H$9:$H$68/'Base de Datos'!$F$9:$F$68*(1+IF('Base de Datos'!$I$9:$I$68="",0,'Base de Datos'!$I$9:$I$68)),MATCH(B15,'Base de Datos'!$B$9:$B$68,0)),IFERROR(INDEX('Sub-recetas'!$D$428:$D$442,MATCH(B15,'Sub-recetas'!$C$428:$C$442,0)),0)))} -> 50960
B16: Cacao en polvo | C16: 60 | D16: gramo | E16: {=IF(OR(B16="",C16=""),"",C16*IFERROR(INDEX('Base de Datos'!$H$9:$H$68/'Base de Datos'!$F$9:$F$68*(1+IF('Base de Datos'!$I$9:$I$68="",0,'Base de Datos'!$I$9:$I$68)),MATCH(B16,'Base de Datos'!$B$9:$B$68,0)),IFERROR(INDEX('Sub-recetas'!$D$428:$D$442,MATCH(B16,'Sub-recetas'!$C$428:$C$442,0)),0)))} -> 151200
B17: Manteca | C17: 120 | D17: gramo | E17: {=IF(OR(B17="",C17=""),"",C17*IFERROR(INDEX('Base de Datos'!$H$9:$H$68/'Base de Datos'!$F$9:$F$68*(1+IF('Base de Datos'!$I$9:$I$68="",0,'Base de Datos'!$I$9:$I$68)),MATCH(B17,'Base de Datos'!$B$9:$B$68,0)),IFERROR(INDEX('Sub-recetas'!$D$428:$D$442,MATCH(B17,'Sub-recetas'!$C$428:$C$442,0)),0)))} -> 343200
B18: Huevos | C18: 4 | D18: unidad | E18: {=IF(OR(B18="",C18=""),"",C18*IFERROR(INDEX('Base de Datos'!$H$9:$H$68/'Base de Datos'!$F$9:$F$68*(1+IF('Base de Datos'!$I$9:$I$68="",0,'Base de Datos'!$I$9:$I$68)),MATCH(B18,'Base de Datos'!$B$9:$B$68,0)),IFERROR(INDEX('Sub-recetas'!$D$428:$D$442,MATCH(B18,'Sub-recetas'!$C$428:$C$442,0)),0)))} -> 1600
B19: Leche entera | C19: 180 | D19: ml | E19: {=IF(OR(B19="",C19=""),"",C19*IFERROR(INDEX('Base de Datos'!$H$9:$H$68/'Base de Datos'!$F$9:$F$68*(1+IF('Base de Datos'!$I$9:$I$68="",0,'Base de Datos'!$I$9:$I$68)),MATCH(B19,'Base de Datos'!$B$9:$B$68,0)),IFERROR(INDEX('Sub-recetas'!$D$428:$D$442,MATCH(B19,'Sub-recetas'!$C$428:$C$442,0)),0)))} -> 229500
B20: Polvo de hornear | C20: 5 | D20: gramo | E20: {=IF(OR(B20="",C20=""),"",C20*IFERROR(INDEX('Base de Datos'!$H$9:$H$68/'Base de Datos'!$F$9:$F$68*(1+IF('Base de Datos'!$I$9:$I$68="",0,'Base de Datos'!$I$9:$I$68)),MATCH(B20,'Base de Datos'!$B$9:$B$68,0)),IFERROR(INDEX('Sub-recetas'!$D$428:$D$442,MATCH(B20,'Sub-recetas'!$C$428:$C$442,0)),0)))} -> 60600
B21: Vainilla esencia | C21: 5 | D21: ml | E21: {=IF(OR(B21="",C21=""),"",C21*IFERROR(INDEX('Base de Datos'!$H$9:$H$68/'Base de Datos'!$F$9:$F$68*(1+IF('Base de Datos'!$I$9:$I$68="",0,'Base de Datos'!$I$9:$I$68)),MATCH(B21,'Base de Datos'!$B$9:$B$68,0)),IFERROR(INDEX('Sub-recetas'!$D$428:$D$442,MATCH(B21,'Sub-recetas'!$C$428:$C$442,0)),0)))} -> 32825
B22: Packaging caja | C22: 1 | D22: unidad | E22: {=IF(OR(B22="",C22=""),"",C22*IFERROR(INDEX('Base de Datos'!$H$9:$H$68/'Base de Datos'!$F$9:$F$68*(1+IF('Base de Datos'!$I$9:$I$68="",0,'Base de Datos'!$I$9:$I$68)),MATCH(B22,'Base de Datos'!$B$9:$B$68,0)),IFERROR(INDEX('Sub-recetas'!$D$428:$D$442,MATCH(B22,'Sub-recetas'!$C$428:$C$442,0)),0)))} -> 105
E23: {=IF(OR(B23="",C23=""),"",C23*IFERROR(INDEX('Base de Datos'!$H$9:$H$68/'Base de Datos'!$F$9:$F$68*(1+IF('Base de Datos'!$I$9:$I$68="",0,'Base de Datos'!$I$9:$I$68)),MATCH(B23,'Base de Datos'!$B$9:$B$68,0)),IFERROR(INDEX('Sub-recetas'!$D$428:$D$442,MATCH(B23,'Sub-recetas'!$C$428:$C$442,0)),0)))}
E24: {=IF(OR(B24="",C24=""),"",C24*IFERROR(INDEX('Base de Datos'!$H$9:$H$68/'Base de Datos'!$F$9:$F$68*(1+IF('Base de Datos'!$I$9:$I$68="",0,'Base de Datos'!$I$9:$I$68)),MATCH(B24,'Base de Datos'!$B$9:$B$68,0)),IFERROR(INDEX('Sub-recetas'!$D$428:$D$442,MATCH(B24,'Sub-recetas'!$C$428:$C$442,0)),0)))}
E25: {=IF(OR(B25="",C25=""),"",C25*IFERROR(INDEX('Base de Datos'!$H$9:$H$68/'Base de Datos'!$F$9:$F$68*(1+IF('Base de Datos'!$I$9:$I$68="",0,'Base de Datos'!$I$9:$I$68)),MATCH(B25,'Base de Datos'!$B$9:$B$68,0)),IFERROR(INDEX('Sub-recetas'!$D$428:$D$442,MATCH(B25,'Sub-recetas'!$C$428:$C$442,0)),0)))}
E26: {=IF(OR(B26="",C26=""),"",C26*IFERROR(INDEX('Base de Datos'!$H$9:$H$68/'Base de Datos'!$F$9:$F$68*(1+IF('Base de Datos'!$I$9:$I$68="",0,'Base de Datos'!$I$9:$I$68)),MATCH(B26,'Base de Datos'!$B$9:$B$68,0)),IFERROR(INDEX('Sub-recetas'!$D$428:$D$442,MATCH(B26,'Sub-recetas'!$C$428:$C$442,0)),0)))}
E27: {=IF(OR(B27="",C27=""),"",C27*IFERROR(INDEX('Base de Datos'!$H$9:$H$68/'Base de Datos'!$F$9:$F$68*(1+IF('Base de Datos'!$I$9:$I$68="",0,'Base de Datos'!$I$9:$I$68)),MATCH(B27,'Base de Datos'!$B$9:$B$68,0)),IFERROR(INDEX('Sub-recetas'!$D$428:$D$442,MATCH(B27,'Sub-recetas'!$C$428:$C$442,0)),0)))}
E28: {=IF(OR(B28="",C28=""),"",C28*IFERROR(INDEX('Base de Datos'!$H$9:$H$68/'Base de Datos'!$F$9:$F$68*(1+IF('Base de Datos'!$I$9:$I$68="",0,'Base de Datos'!$I$9:$I$68)),MATCH(B28,'Base de Datos'!$B$9:$B$68,0)),IFERROR(INDEX('Sub-recetas'!$D$428:$D$442,MATCH(B28,'Sub-recetas'!$C$428:$C$442,0)),0)))}
E29: {=IF(OR(B29="",C29=""),"",C29*IFERROR(INDEX('Base de Datos'!$H$9:$H$68/'Base de Datos'!$F$9:$F$68*(1+IF('Base de Datos'!$I$9:$I$68="",0,'Base de Datos'!$I$9:$I$68)),MATCH(B29,'Base de Datos'!$B$9:$B$68,0)),IFERROR(INDEX('Sub-recetas'!$D$428:$D$442,MATCH(B29,'Sub-recetas'!$C$428:$C$442,0)),0)))}
E30: {=IF(OR(B30="",C30=""),"",C30*IFERROR(INDEX('Base de Datos'!$H$9:$H$68/'Base de Datos'!$F$9:$F$68*(1+IF('Base de Datos'!$I$9:$I$68="",0,'Base de Datos'!$I$9:$I$68)),MATCH(B30,'Base de Datos'!$B$9:$B$68,0)),IFERROR(INDEX('Sub-recetas'!$D$428:$D$442,MATCH(B30,'Sub-recetas'!$C$428:$C$442,0)),0)))}
B31: TOTAL COSTO INGREDIENTES + PACKAGING | E31: =SUM(E14:E30) -> 911990
B34: RESUMEN Y PRECIO SUGERIDO
B35: Costo ingredientes + packaging: | F35: =E31 -> 911990
B36: + Merma de producción (%): | F36: =E31*E7 -> 45599.5
B37: + % Margen de error / variación: | F37: 0.05
B38: COSTO TOTAL (con margen de variación): | F38: =F35+F36+IF(F37="",0,F35*F37) -> 1003189
B40: % Margen de ganancia: | F40: =E8 -> 0.65
B41: PRECIO SIN IMPUESTOS: | F41: =IF(AND(F38<>"",E8>0),IF(E6>0,F38/E6,F38)/(1-E8),"") -> 2866254.3
B42: + IVA / impuesto (%): | F42: =Configuracion!D11 -> 0.21
B43: PRECIO CON IMPUESTOS: | F43: =IF(F41<>"",F41*(1+F42),"") -> 3468167.7
B45: % Margen de ganancia real: | F45: =IF(AND(F38<>"",F41<>""),IF(E6>0,1-(F38/E6)/F41,1-F38/F41),"") -> 0.65
B46: Ganancia por unidad ($): | F46: =IF(F41<>"",F41-IF(E6>0,F38/E6,F38),"") -> 1863065.3
B48: SEMÁFORO DE PRECIO: | F48: =IF(F41="","⚪ Completá los datos",IF(1-IF(E6>0,F38/E6,F38)/F41>=Configuracion!D9,"🟢 PRECIO OK — Tu margen supera la meta",IF(1-IF(E6>0,F38/E6,F38)/F41>=Configuracion!D9-0.1,"🟡 AJUSTAR — Margen cercano a la meta","🔴 REVISAR — Margen por debajo de la meta"))) -> 🟢 PRECIO OK — Tu margen supera la meta
...

Sheet Receta 02
A1: 🍳 RECETA 02
B4: DATOS DE LA RECETA
B5: Nombre: | E5: Alfajor de maicena
B6: Porciones / unidades: | E6: 1
B7: % Merma de producción: | E7: 0.03
B8: % Margen de ganancia: | E8: =Configuracion!D9 -> 0.65
B9: Precio de venta actual ($): | E9: 1800
B10: Fecha último costeo: | E10: 46109
B11: =IF(E10="","⚪ Ingresá la fecha de costeo.",IF((TODAY()-E10)>90,"🔴 Hace más de 90 días sin revisar — actualizá los costos","🟢 Al día — revisada hace "&(TODAY()-E10)&" días")) -> 🟢 Al día — revisada hace 28 días
B13: INGREDIENTE / SUB-RECETA | C13: CANTIDAD POR PORCIÓN | D13: UNIDAD DE MEDIDA | E13: COSTO DE PRODUCCIÓN ($)
B14: Maicena | C14: 30 | D14: gramo | E14: {=IF(OR(B14="",C14=""),"",C14*IFERROR(INDEX('Base de Datos'!$H$9:$H$68/'Base de Datos'!$F$9:$F$68*(1+IF('Base de Datos'!$I$9:$I$68="",0,'Base de Datos'!$I$9:$I$68)),MATCH(B14,'Base de Datos'!$B$9:$B$68,0)),IFERROR(INDEX('Sub-recetas'!$D$428:$D$442,MATCH(B14,'Sub-recetas'!$C$428:$C$442,0)),0)))} -> 49725
B15: Harina 000 | C15: 20 | D15: gramo | E15: {=IF(OR(B15="",C15=""),"",C15*IFERROR(INDEX('Base de Datos'!$H$9:$H$68/'Base de Datos'!$F$9:$F$68*(1+IF('Base de Datos'!$I$9:$I$68="",0,'Base de Datos'!$I$9:$I$68)),MATCH(B15,'Base de Datos'!$B$9:$B$68,0)),IFERROR(INDEX('Sub-recetas'!$D$428:$D$442,MATCH(B15,'Sub-recetas'!$C$428:$C$442,0)),0)))} -> 3360
B16: Azúcar impalpable | C16: 25 | D16: gramo | E16: {=IF(OR(B16="",C16=""),"",C16*IFERROR(INDEX('Base de Datos'!$H$9:$H$68/'Base de Datos'!$F$9:$F$68*(1+IF('Base de Datos'!$I$9:$I$68="",0,'Base de Datos'!$I$9:$I$68)),MATCH(B16,'Base de Datos'!$B$9:$B$68,0)),IFERROR(INDEX('Sub-recetas'!$D$428:$D$442,MATCH(B16,'Sub-recetas'!$C$428:$C$442,0)),0)))} -> 57750
B17: Manteca | C17: 35 | D17: gramo | E17: {=IF(OR(B17="",C17=""),"",C17*IFERROR(INDEX('Base de Datos'!$H$9:$H$68/'Base de Datos'!$F$9:$F$68*(1+IF('Base de Datos'!$I$9:$I$68="",0,'Base de Datos'!$I$9:$I$68)),MATCH(B17,'Base de Datos'!$B$9:$B$68,0)),IFERROR(INDEX('Sub-recetas'!$D$428:$D$442,MATCH(B17,'Sub-recetas'!$C$428:$C$442,0)),0)))} -> 100100
B18: Huevos | C18: 0.5 | D18: unidad | E18: {=IF(OR(B18="",C18=""),"",C18*IFERROR(INDEX('Base de Datos'!$H$9:$H$68/'Base de Datos'!$F$9:$F$68*(1+IF('Base de Datos'!$I$9:$I$68="",0,'Base de Datos'!$I$9:$I$68)),MATCH(B18,'Base de Datos'!$B$9:$B$68,0)),IFERROR(INDEX('Sub-recetas'!$D$428:$D$442,MATCH(B18,'Sub-recetas'!$C$428:$C$442,0)),0)))} -> 200
B19: Dulce de leche | C19: 40 | D19: gramo | E19: {=IF(OR(B19="",C19=""),"",C19*IFERROR(INDEX('Base de Datos'!$H$9:$H$68/'Base de Datos'!$F$9:$F$68*(1+IF('Base de Datos'!$I$9:$I$68="",0,'Base de Datos'!$I$9:$I$68)),MATCH(B19,'Base de Datos'!$B$9:$B$68,0)),IFERROR(INDEX('Sub-recetas'!$D$428:$D$442,MATCH(B19,'Sub-recetas'!$C$428:$C$442,0)),0)))} -> 46800
B20: Coco rallado | C20: 5 | D20: gramo | E20: {=IF(OR(B20="",C20=""),"",C20*IFERROR(INDEX('Base de Datos'!$H$9:$H$68/'Base de Datos'!$F$9:$F$68*(1+IF('Base de Datos'!$I$9:$I$68="",0,'Base de Datos'!$I$9:$I$68)),MATCH(B20,'Base de Datos'!$B$9:$B$68,0)),IFERROR(INDEX('Sub-recetas'!$D$428:$D$442,MATCH(B20,'Sub-recetas'!$C$428:$C$442,0)),0)))} -> 12240
B21: Packaging bolsa | C21: 0.05 | D21: unidad | E21: {=IF(OR(B21="",C21=""),"",C21*IFERROR(INDEX('Base de Datos'!$H$9:$H$68/'Base de Datos'!$F$9:$F$68*(1+IF('Base de Datos'!$I$9:$I$68="",0,'Base de Datos'!$I$9:$I$68)),MATCH(B21,'Base de Datos'!$B$9:$B$68,0)),IFERROR(INDEX('Sub-recetas'!$D$428:$D$442,MATCH(B21,'Sub-recetas'!$C$428:$C$442,0)),0)))} -> 4.4
E22: {=IF(OR(B22="",C22=""),"",C22*IFERROR(INDEX('Base de Datos'!$H$9:$H$68/'Base de Datos'!$F$9:$F$68*(1+IF('Base de Datos'!$I$9:$I$68="",0,'Base de Datos'!$I$9:$I$68)),MATCH(B22,'Base de Datos'!$B$9:$B$68,0)),IFERROR(INDEX('Sub-recetas'!$D$428:$D$442,MATCH(B22,'Sub-recetas'!$C$428:$C$442,0)),0)))}
E23: {=IF(OR(B23="",C23=""),"",C23*IFERROR(INDEX('Base de Datos'!$H$9:$H$68/'Base de Datos'!$F$9:$F$68*(1+IF('Base de Datos'!$I$9:$I$68="",0,'Base de Datos'!$I$9:$I$68)),MATCH(B23,'Base de Datos'!$B$9:$B$68,0)),IFERROR(INDEX('Sub-recetas'!$D$428:$D$442,MATCH(B23,'Sub-recetas'!$C$428:$C$442,0)),0)))}
E24: {=IF(OR(B24="",C24=""),"",C24*IFERROR(INDEX('Base de Datos'!$H$9:$H$68/'Base de Datos'!$F$9:$F$68*(1+IF('Base de Datos'!$I$9:$I$68="",0,'Base de Datos'!$I$9:$I$68)),MATCH(B24,'Base de Datos'!$B$9:$B$68,0)),IFERROR(INDEX('Sub-recetas'!$D$428:$D$442,MATCH(B24,'Sub-recetas'!$C$428:$C$442,0)),0)))}
E25: {=IF(OR(B25="",C25=""),"",C25*IFERROR(INDEX('Base de Datos'!$H$9:$H$68/'Base de Datos'!$F$9:$F$68*(1+IF('Base de Datos'!$I$9:$I$68="",0,'Base de Datos'!$I$9:$I$68)),MATCH(B25,'Base de Datos'!$B$9:$B$68,0)),IFERROR(INDEX('Sub-recetas'!$D$428:$D$442,MATCH(B25,'Sub-recetas'!$C$428:$C$442,0)),0)))}
E26: {=IF(OR(B26="",C26=""),"",C26*IFERROR(INDEX('Base de Datos'!$H$9:$H$68/'Base de Datos'!$F$9:$F$68*(1+IF('Base de Datos'!$I$9:$I$68="",0,'Base de Datos'!$I$9:$I$68)),MATCH(B26,'Base de Datos'!$B$9:$B$68,0)),IFERROR(INDEX('Sub-recetas'!$D$428:$D$442,MATCH(B26,'Sub-recetas'!$C$428:$C$442,0)),0)))}
